Workbook
Name Active_Engine_Ref: 'CHART DATA'!$M$2
Name Age_Range: 'CHART DATA'!$A$2:INDEX('CHART DATA'!$A$2:$A$102,Horizon_Rows)
Name AgeContrib_Range: 'CHART DATA'!$N$2:INDEX('CHART DATA'!$N$2:$N$102,Horizon_Rows)
Name AgeMilestone_Range: 'CHART DATA'!$H$2:INDEX('CHART DATA'!$H$2:$H$102,Horizon_Rows)
Name Bracket_Round_MFS: 'CONSTANTS & REFERENCES'!$B$17
Name Bracket_Round_Standard: 'CONSTANTS & REFERENCES'!$B$16
Name Contribution_Range: 'CHART DATA'!$O$2:INDEX('CHART DATA'!$O$2:$O$102,Horizon_Rows)
Name DisposablePay_Range: 'CHART DATA'!$F$2:INDEX('CHART DATA'!$F$2:$F$102,Horizon_Rows)
Name FedTax_Range: 'CHART DATA'!$S$2:INDEX('CHART DATA'!$S$2:$S$102,Horizon_Rows)
Name Growth_Range: 'CHART DATA'!$P$2:INDEX('CHART DATA'!$P$2:$P$102,Horizon_Rows)
Name GrowthMultiple_Range: 'PERIODIC ENGINE'!$L$2:INDEX('PERIODIC ENGINE'!$L$2:$L$102,Horizon_Rows)
Name Head_Household_STD_Deduction: #REF!
Name Horizon_Rows: 'CHART DATA'!$AZ$2
Name Horizon_Years: 'CHART DATA'!$AY$2
Name Inp_Age_Retire: #REF!
Name Inp_Age_Start: #REF!
Name Inp_Rate_Inf: #REF!
Name Inp_Wage_Base: #REF!
Name Inp_Wage_Merit: #REF!
Name IRA_Base: #REF!
Name IRA_Catch_Base: #REF!
Name IRA_Catch_Step: #REF!
Name IRA_Step: #REF!
Name Joint_Spouse_STD_Deduction: #REF!
Name Limit_OASDI: #REF!
Name Med_Threshold: #REF!
Name NominalBal_Range: 'CHART DATA'!$B$2:INDEX('CHART DATA'!$B$2:$B$102,Horizon_Rows)
Name NominalMilestone_Range: 'CHART DATA'!$I$2:INDEX('CHART DATA'!$I$2:$I$102,Horizon_Rows)
Name Payroll_Range: 'CHART DATA'!$U$2:INDEX('CHART DATA'!$U$2:$U$102,Horizon_Rows)
Name ProjYear_Range: 'CHART DATA'!$E$2:INDEX('CHART DATA'!$E$2:$E$102,Horizon_Rows)
Name ProjYearTax_Range: 'CHART DATA'!$R$2:INDEX('CHART DATA'!$R$2:$R$102,Horizon_Rows)
Name Rate_Med: #REF!
Name Rate_OASDI: #REF!
Name RealBal_Range: 'CHART DATA'!$C$2:INDEX('CHART DATA'!$C$2:$C$102,Horizon_Rows)
Name Single_Separately_STD_Deduction: #REF!
Name StateTax_Range: 'CHART DATA'!$T$2:INDEX('CHART DATA'!$T$2:$T$102,Horizon_Rows)
Name TakeHome_Range: 'CHART DATA'!$V$2:INDEX('CHART DATA'!$V$2:$V$102,Horizon_Rows)
Name Tax_Step: #REF!
Name TerminalValueByYear_Range: 'PERIODIC ENGINE'!$Q$2:INDEX('PERIODIC ENGINE'!$Q$2:$Q$102,Horizon_Rows)
Name Threshold1M_Range: 'CHART DATA'!$K$2:INDEX('CHART DATA'!$K$2:$K$102,Horizon_Rows)
Name Threshold2M_Range: 'CHART DATA'!$L$2:INDEX('CHART DATA'!$L$2:$L$102,Horizon_Rows)
Name Threshold500k_Range: 'CHART DATA'!$J$2:INDEX('CHART DATA'!$J$2:$J$102,Horizon_Rows)

Sheet README
A1: IRA RETIREMENT MODEL
A2: Instructions, methodology, assumptions, and limitations
A4: PURPOSE
A5: This workbook projects an IRA balance from a starting age through retirement using transparent annual time-value-of-money formulas.
A7: HOW TO USE THE MODEL
A8: 1. Open INPUTS and answer the highlighted questions.
A9: 2. Select whether contributions occur at the beginning or end of each year.
A10: 3. Review the year-by-year roll-forward on ENGINE.
A11: 4. Review retirement results and the nominal-versus-real chart on OUTPUT.
A12: 5. Actuary Mode stores career assumptions for a future salary module; it does not currently change IRA accumulation.
A14: WORKBOOK STRUCTURE
A15: Sheet | B15: Purpose | C15: User action
A16: INPUTS | B16: Conversational assumptions | C16: Edit the highlighted cells
A17: ENGINE | B17: Annual accumulation schedule | C17: Review formulas and audit trail
A18: OUTPUT | B18: Review retirement results | C18: Review retirement results
A19: MILESTONES | B19: First-year threshold analysis for $500k, $1m, and $2m balances | C19: Review
A20: CONSTANTS & REFERENCES | B20: Research notes and future official-source inputs | C20: Review / update
A21: EXAM FM CONCEPTS
A22: Concept | B22: Formula demonstrated | C22: Purpose
A23: Compound accumulation | B23: Beginning Balance × (1 + annual return) | C23: Annual interest accumulation
A24: Growing contributions | B24: Initial Contribution × (1 + growth)^(t − delay − 1) | C24: Contributions made over time
A25: Real balance | B25: Nominal Ending Balance ÷ Inflation Index | C25: Inflation-adjusted retirement value
A26: Future-value cross-check | B26: FV for starting balance + sum of each contribution's FV | C26: Independent validation of the roll-forward
A28: ASSUMPTIONS & LIMITATIONS
A29: Returns, inflation, and contribution growth are flat effective annual assumptions, not forecasts.
A30: The model includes a simplified 2026 federal income-tax module, Social Security and Medicare payroll taxes, and an optional illustrative flat state income tax. It does not model credits, itemized deductions, local taxes, or employer benefits.
A31: Illustrative IRA contribution limits are indexed within the model. Roth eligibility, MAGI phase-outs, earned-income limits, and future official IRS limits are not modeled. | C31: n
A32: Educational project only; not tax, legal, actuarial, or investment advice.
A33: Tax interface note: the filing status can change after a user-selected number of projection years. State tax is intentionally simplified and applies a flat rate to federal taxable income.
A37: PERIODIC CONTRIBUTION MODEL
A38: The annual effective investment return is converted using (1 + annual return)^(1 / selected periods per year) - 1. Users do not enter a separate periodic return.
A39: The annual modeled Roth limit remains indexed once per projection year and is divided evenly across the selected contribution periods.
A40: Advanced mode uses 252 trading days divided by the selected valid interval. IRA and C-CPI-U indexing remain annual in both standard and advanced modes.

Sheet INPUTS
B2: Let’s build your IRA projection.
B3: Answer the highlighted questions and the model will project your account over time.
B5: Let’s start with your IRA
B6: What's your starting age? | C6: 22 | D6: years
B7: At what age do you plan to retire? | C7: 65 | D7: years
B8: What's your current IRA balance? | C8: 0 | D8: nominal dollars
B9: How often will you contribute to your IRA? | C9: Annual | D9: =IF($C$39="On","Ignored while advanced trading-day contributions are On","Annual, Semiannual, Quarterly, Monthly, Biweekly, or Weekly") -> Annual, Semiannual, Quarterly, Monthly, Biweekly, or Weekly
B10: What annual investment return should we assume? | C10: 0.1 | D10: nominal effective annual rate
B11: What annual inflation rate should we assume? | C11: 0.06 | D11: flat effective annual rate
B12: When during the year will you contribute? | C12: Beginning | D12: Beginning or End
B13: How many years will you wait before contributing? | C13: 0 | D13: full years skipped before the first contribution
B14: Now let’s add your tax and career assumptions
B15: What annual merit raise should we assume? | C15: 0.03 | D15: effective annual rate
B16: What's your starting salary? | C16: 70000 | D16: annual salary
B17: Cap your salary growth? | C17: No | D17: Yes or No
B18: What's the maximum salary you'd like to model? | C18: 275000 | D18: Salary will never exceed this amount | E18: =IF($C$17="Yes","Active","Ignored while cap is No") -> Ignored while cap is No
B19: What federal filing status should we use? | C19: Single | D19: Single, Married Filing Jointly, Married Filing Separately, or Head of Household
B20: Include an illustrative flat state income tax? | C20: No | D20: Simplified state-tax option only
B21: What illustrative flat state income tax rate should we assume? | C21: 0 | D21: Applied to federal taxable income
B22: Illustrative flat state income tax does not model individual state tax codes, credits, deductions, local taxes, or special rules.
B25: Optional & Advanced Inputs
B26: Now let’s add your actuarial career assumptions
B27: Actuary Mode on? | C27: Yes | D27: Yes or No | E27: Controls exam and credential bonuses
B28: Credential Status | C28: ASA / ACAS | D28: Determines which career bonuses still apply | E28: =IF($C$27="Yes","Active","Ignored while Actuary Mode is No") -> Active
B29: If you're already ASA/ACAS or FSA/FCAS, we assume your entered starting salary already reflects those bonuses (we won't add them again).
B30: How many exams do you have left to pass? | C30: 3 | D30: exams remaining (caps cumulative exam bonus) | E30: =IF($C$27<>"Yes","Ignored while Actuary Mode is No",IF($C$28="FSA / FCAS","Already reflected in starting salary","Active")) -> Active
B31: What's the salary raise for each exam passed? | C31: 3000 | D31: per exam pass | E31: =IF($C$27<>"Yes","Ignored while Actuary Mode is No",IF($C$28="FSA / FCAS","Already reflected in starting salary","Active")) -> Active
B32: What's the salary raise when you earn Associate status? | C32: 15000 | D32: one-time increase | E32: =IF($C$27<>"Yes","Ignored while Actuary Mode is No",IF(OR($C$28="ASA / ACAS",$C$28="FSA / FCAS"),"Already reflected in starting salary","Active")) -> Already reflected in starting salary
B33: How many years until Associate status? | C33: 5 | D33: years from today | E33: =IF($C$27<>"Yes","Ignored while Actuary Mode is No",IF(OR($C$28="ASA / ACAS",$C$28="FSA / FCAS"),"Already reflected in starting salary","Active")) -> Already reflected in starting salary
B34: What's the salary raise when you earn Fellowship status? | C34: 15000 | D34: one-time increase | E34: =IF($C$27<>"Yes","Ignored while Actuary Mode is No",IF($C$28="FSA / FCAS","Already reflected in starting salary","Active")) -> Active
B35: How many years until Fellowship? | C35: 4 | D35: years from today | E35: =IF($C$27<>"Yes","Ignored while Actuary Mode is No",IF($C$28="FSA / FCAS","Already reflected in starting salary","Active")) -> Active
B36: How many years until you finish passing exams? | C36: 4 | D36: years (pace = exams remaining ÷ this) | E36: =IF($C$27<>"Yes","Ignored while Actuary Mode is No",IF($C$28="FSA / FCAS","Already reflected in starting salary","Active")) -> Active
B37: Exams Per Year (derived pace) | C37: =IF(C36=0,"—",C30/C36) -> 0.75 | D37: exams remaining ÷ years to finish | E37: =IF($C$27<>"Yes","Ignored while Actuary Mode is No",IF($C$28="FSA / FCAS","Already reflected in starting salary","Calculated")) -> Calculated
B38: Advanced periodic contribution mode
B39: Enable advanced trading-day contributions? | C39: Off | D39: Off uses the frequency selected above; On uses a trading-day interval
B40: Contribute every how many trading days? | C40: 18 | D40: Choose an interval that divides 252 evenly
B41: Trading-Day Contributions per Year | C41: =IF(C39="On",252/C40,"") | D41: 252 trading days ÷ selected interval
B42: Contribution per Trading-Day Period | C42: =IF(C39="On",IFERROR(ENGINE!J2/C41,0),"") | D42: Statutory Roth limit (Year 0) divided by trading-day contributions. This is the limit only, not the delayed actual contribution.
B43: Do you expect your filing status to change? | C43: Yes | D43: Choose Yes to activate the transition inputs
B44: What filing status should we use after the change? | C44: Married Filing Jointly | D44: Applied beginning in the selected projection year
...

Sheet OUTPUT - SUMMARY
A1: IRA Projection Summary
A2: High-level retirement and disposable-income outcomes from the current model assumptions.
A4: Key Results
A6: Final nominal Roth balance | B6: {=LOOKUP(2,1/('CHART DATA'!B2:B102<>""),'CHART DATA'!B2:B102)} -> 11101633
A7: Final real Roth balance | B7: {=LOOKUP(2,1/('CHART DATA'!C2:C102<>""),'CHART DATA'!C2:C102)} -> 906222.15
A8: Total contributions | B8: {=LOOKUP(2,1/('PERIODIC ENGINE'!K2:K102<>""),'PERIODIC ENGINE'!K2:K102)} -> 1630400
A9: Total investment growth | B9: =B6-INPUTS!C8-B8 -> 9471233.3
A10: Money multiplier | B10: =IFERROR(B6/(B8+INPUTS!C8),0) -> 6.809147
A11: Final disposable take-home pay | B11: {=LOOKUP(2,1/(ENGINE!AI2:AI102<>""),ENGINE!AI2:AI102)-LOOKUP(2,1/(ENGINE!D2:D102<>""),ENGINE!D2:D102)} -> 194530.73
A12: The money multiplier above is just an average across all your contributions. The chart below shows why that average hides a wide range.
A13: First contribution's growth multiple | B13: {=INDEX('PERIODIC ENGINE'!L2:L102,MATCH(TRUE,INDEX(ENGINE!D2:D102>0,0),0))} -> 66.264076
A14: Final contribution's growth multiple | B14: {=INDEX('PERIODIC ENGINE'!L2:L102,Horizon_Rows)} -> 1.1
A15: First contribution's terminal value | B15: {=INDEX('PERIODIC ENGINE'!Q2:Q102,MATCH(TRUE,INDEX(ENGINE!D2:D102>0,0),0))} -> 496980.57
A16: Final contribution's terminal value | B16: {=INDEX('PERIODIC ENGINE'!Q2:Q102,Horizon_Rows)} -> 115390
A17: Starting balance's terminal value | B17: =INPUTS!$C$8*(1+'PERIODIC ENGINE'!$S$5)^(Horizon_Rows*'PERIODIC ENGINE'!$S$3) -> 0
A18: Cross-check: seed + all contributions' terminal values vs. actual ending balance | B18: {=ROUND((B17+SUM('PERIODIC ENGINE'!$Q$2:$Q$102))-INDEX('PERIODIC ENGINE'!$J$2:$J$102,Horizon_Rows),2)} -> 0
A19: ="Your dollars didn't grow equally: "&TEXT(B13,"0.0")&"x for your earliest contribution vs. "&TEXT(B14,"0.0")&"x for your last, because early money compounds longer. Your first year's contributions grew into "&TEXT(B15,"$#,##0")&", and your final year's grew into "&TEXT(B16,"$#,##0")&". The charts show the full curve." -> Your dollars didn't grow equally: 66.3x for your earliest contribution vs. 1.1x for your last, because early money compounds longer. Your first year's contributions grew into $496,981, and your final year's grew into $115,390. The charts show the full curve.
A22: Lifetime Tax Summary
A24: Cumulative taxes paid | B24: =SUM(ENGINE!AH2:AH102) -> 911070.78
A25: Cumulative Social Security (OASDI) tax paid | B25: =SUM(ENGINE!AE2:AE102) -> 501452.51
A26: Cumulative gross income earned | B26: =SUM(ENGINE!Y2:Y102) -> 8087943.7
A27: Cumulative effective tax rate | B27: =IFERROR(B24/B26,0) -> 0.11264554
A28: Cumulative effective take-home rate | B28: =1-B27 -> 0.88735446

Sheet OUTPUT - RETIREMENT
A1: IRA Retirement Detail
A2: Annual accumulation, contribution, investment-growth, and inflation-adjusted balances.
A4: Retirement Results
A6: Final nominal balance | B6: ='OUTPUT - SUMMARY'!B6 -> 11101633
A7: Final real balance | B7: ='OUTPUT - SUMMARY'!B7 -> 906222.15
A8: Total contributions | B8: ='OUTPUT - SUMMARY'!B8 -> 1630400
A9: Total investment growth | B9: ='OUTPUT - SUMMARY'!B9 -> 9471233.3
A12: Projection Year | B12: Age | C12: Annual Contribution | D12: Annual Investment Growth | E12: Ending Nominal Balance | F12: Ending Real Balance | G12: Cumulative Contributions | H12: Cumulative Investment Growth | I12: Terminal Value of Contributions
A13: =IF(ENGINE!A2="","",ENGINE!A2) -> 0 | B13: =IF(A13="","",ENGINE!B2) -> 22 | C13: =IF(A13="","",ENGINE!D2) -> 7500 | D13: =IF(A13="","",INDEX('PERIODIC ENGINE'!$I$2:$I$102,MATCH(A13,'PERIODIC ENGINE'!$A$2:$A$102,0))) -> 750 | E13: =IF(A13="","",'CHART DATA'!B2) -> 8250 | F13: =IF(A13="","",'CHART DATA'!C2) -> 8250 | G13: =IF(A13="","",INDEX('PERIODIC ENGINE'!$K$2:$K$102,MATCH(A13,'PERIODIC ENGINE'!$A$2:$A$102,0))) -> 7500 | H13: =IF(A13="","",E13-INPUTS!$C$8-G13) -> 750 | I13: {=IF(A13="","",IFERROR(INDEX(TerminalValueByYear_Range,ROW()-ROW($I$13)+1),""))} -> 496980.57
A14: =IF(ENGINE!A3="","",ENGINE!A3) -> 1 | B14: =IF(A14="","",ENGINE!B3) -> 23 | C14: =IF(A14="","",ENGINE!D3) -> 7500 | D14: =IF(A14="","",INDEX('PERIODIC ENGINE'!$I$2:$I$102,MATCH(A14,'PERIODIC ENGINE'!$A$2:$A$102,0))) -> 1575 | E14: =IF(A14="","",'CHART DATA'!B3) -> 17325 | F14: =IF(A14="","",'CHART DATA'!C3) -> 16344.34 | G14: =IF(A14="","",INDEX('PERIODIC ENGINE'!$K$2:$K$102,MATCH(A14,'PERIODIC ENGINE'!$A$2:$A$102,0))) -> 15000 | H14: =IF(A14="","",E14-INPUTS!$C$8-G14) -> 2325 | I14: {=IF(A14="","",IFERROR(INDEX(TerminalValueByYear_Range,ROW()-ROW($I$13)+1),""))} -> 451800.52
A15: =IF(ENGINE!A4="","",ENGINE!A4) -> 2 | B15: =IF(A15="","",ENGINE!B4) -> 24 | C15: =IF(A15="","",ENGINE!D4) -> 8000 | D15: =IF(A15="","",INDEX('PERIODIC ENGINE'!$I$2:$I$102,MATCH(A15,'PERIODIC ENGINE'!$A$2:$A$102,0))) -> 2532.5 | E15: =IF(A15="","",'CHART DATA'!B4) -> 27857.5 | F15: =IF(A15="","",'CHART DATA'!C4) -> 24793.076 | G15: =IF(A15="","",INDEX('PERIODIC ENGINE'!$K$2:$K$102,MATCH(A15,'PERIODIC ENGINE'!$A$2:$A$102,0))) -> 23000 | H15: =IF(A15="","",E15-INPUTS!$C$8-G15) -> 4857.5 | I15: {=IF(A15="","",IFERROR(INDEX(TerminalValueByYear_Range,ROW()-ROW($I$13)+1),""))} -> 438109.59
A16: =IF(ENGINE!A5="","",ENGINE!A5) -> 3 | B16: =IF(A16="","",ENGINE!B5) -> 25 | C16: =IF(A16="","",ENGINE!D5) -> 8500 | D16: =IF(A16="","",INDEX('PERIODIC ENGINE'!$I$2:$I$102,MATCH(A16,'PERIODIC ENGINE'!$A$2:$A$102,0))) -> 3635.75 | E16: =IF(A16="","",'CHART DATA'!B5) -> 39993.25 | F16: =IF(A16="","",'CHART DATA'!C5) -> 33579.104 | G16: =IF(A16="","",INDEX('PERIODIC ENGINE'!$K$2:$K$102,MATCH(A16,'PERIODIC ENGINE'!$A$2:$A$102,0))) -> 31500 | H16: =IF(A16="","",E16-INPUTS!$C$8-G16) -> 8493.25 | I16: {=IF(A16="","",IFERROR(INDEX(TerminalValueByYear_Range,ROW()-ROW($I$13)+1),""))} -> 423174.04
A17: =IF(ENGINE!A6="","",ENGINE!A6) -> 4 | B17: =IF(A17="","",ENGINE!B6) -> 26 | C17: =IF(A17="","",ENGINE!D6) -> 9000 | D17: =IF(A17="","",INDEX('PERIODIC ENGINE'!$I$2:$I$102,MATCH(A17,'PERIODIC ENGINE'!$A$2:$A$102,0))) -> 4899.325 | E17: =IF(A17="","",'CHART DATA'!B6) -> 53892.575 | F17: =IF(A17="","",'CHART DATA'!C6) -> 42687.967 | G17: =IF(A17="","",INDEX('PERIODIC ENGINE'!$K$2:$K$102,MATCH(A17,'PERIODIC ENGINE'!$A$2:$A$102,0))) -> 40500 | H17: =IF(A17="","",E17-INPUTS!$C$8-G17) -> 13392.575 | I17: {=IF(A17="","",IFERROR(INDEX(TerminalValueByYear_Range,ROW()-ROW($I$13)+1),""))} -> 407333.3
A18: =IF(ENGINE!A7="","",ENGINE!A7) -> 5 | B18: =IF(A18="","",ENGINE!B7) -> 27 | C18: =IF(A18="","",ENGINE!D7) -> 10000 | D18: =IF(A18="","",INDEX('PERIODIC ENGINE'!$I$2:$I$102,MATCH(A18,'PERIODIC ENGINE'!$A$2:$A$102,0))) -> 6389.2575 | E18: =IF(A18="","",'CHART DATA'!B7) -> 70281.833 | F18: =IF(A18="","",'CHART DATA'!C7) -> 52518.674 | G18: =IF(A18="","",INDEX('PERIODIC ENGINE'!$K$2:$K$102,MATCH(A18,'PERIODIC ENGINE'!$A$2:$A$102,0))) -> 50500 | H18: =IF(A18="","",E18-INPUTS!$C$8-G18) -> 19781.833 | I18: {=IF(A18="","",IFERROR(INDEX(TerminalValueByYear_Range,ROW()-ROW($I$13)+1),""))} -> 411447.78
A19: =IF(ENGINE!A8="","",ENGINE!A8) -> 6 | B19: =IF(A19="","",ENGINE!B8) -> 28 | C19: =IF(A19="","",ENGINE!D8) -> 10500 | D19: =IF(A19="","",INDEX('PERIODIC ENGINE'!$I$2:$I$102,MATCH(A19,'PERIODIC ENGINE'!$A$2:$A$102,0))) -> 8078.1833 | E19: =IF(A19="","",'CHART DATA'!B8) -> 88860.016 | F19: =IF(A19="","",'CHART DATA'!C8) -> 62642.805 | G19: =IF(A19="","",INDEX('PERIODIC ENGINE'!$K$2:$K$102,MATCH(A19,'PERIODIC ENGINE'!$A$2:$A$102,0))) -> 61000 | H19: =IF(A19="","",E19-INPUTS!$C$8-G19) -> 27860.016 | I19: {=IF(A19="","",IFERROR(INDEX(TerminalValueByYear_Range,ROW()-ROW($I$13)+1),""))} -> 392745.61
A20: =IF(ENGINE!A9="","",ENGINE!A9) -> 7 | B20: =IF(A20="","",ENGINE!B9) -> 29 | C20: =IF(A20="","",ENGINE!D9) -> 11000 | D20: =IF(A20="","",INDEX('PERIODIC ENGINE'!$I$2:$I$102,MATCH(A20,'PERIODIC ENGINE'!$A$2:$A$102,0))) -> 9986.0016 | E20: =IF(A20="","",'CHART DATA'!B9) -> 109846.02 | F20: =IF(A20="","",'CHART DATA'!C9) -> 73053.875 | G20: =IF(A20="","",INDEX('PERIODIC ENGINE'!$K$2:$K$102,MATCH(A20,'PERIODIC ENGINE'!$A$2:$A$102,0))) -> 72000 | H20: =IF(A20="","",E20-INPUTS!$C$8-G20) -> 37846.017 | I20: {=IF(A20="","",IFERROR(INDEX(TerminalValueByYear_Range,ROW()-ROW($I$13)+1),""))} -> 374043.43
A21: =IF(ENGINE!A10="","",ENGINE!A10) -> 8 | B21: =IF(A21="","",ENGINE!B10) -> 30 | C21: =IF(A21="","",ENGINE!D10) -> 11500 | D21: =IF(A21="","",INDEX('PERIODIC ENGINE'!$I$2:$I$102,MATCH(A21,'PERIODIC ENGINE'!$A$2:$A$102,0))) -> 12134.602 | E21: =IF(A21="","",'CHART DATA'!B10) -> 133480.62 | F21: =IF(A21="","",'CHART DATA'!C10) -> 83747.392 | G21: =IF(A21="","",INDEX('PERIODIC ENGINE'!$K$2:$K$102,MATCH(A21,'PERIODIC ENGINE'!$A$2:$A$102,0))) -> 83500 | H21: =IF(A21="","",E21-INPUTS!$C$8-G21) -> 49980.619 | I21: {=IF(A21="","",IFERROR(INDEX(TerminalValueByYear_Range,ROW()-ROW($I$13)+1),""))} -> 355495.83
A22: =IF(ENGINE!A11="","",ENGINE!A11) -> 9 | B22: =IF(A22="","",ENGINE!B11) -> 31 | C22: =IF(A22="","",ENGINE!D11) -> 12500 | D22: =IF(A22="","",INDEX('PERIODIC ENGINE'!$I$2:$I$102,MATCH(A22,'PERIODIC ENGINE'!$A$2:$A$102,0))) -> 14598.062 | E22: =IF(A22="","",'CHART DATA'!B11) -> 160578.68 | F22: =IF(A22="","",'CHART DATA'!C11) -> 95046.275 | G22: =IF(A22="","",INDEX('PERIODIC ENGINE'!$K$2:$K$102,MATCH(A22,'PERIODIC ENGINE'!$A$2:$A$102,0))) -> 96000 | H22: =IF(A22="","",E22-INPUTS!$C$8-G22) -> 64578.681 | I22: {=IF(A22="","",IFERROR(INDEX(TerminalValueByYear_Range,ROW()-ROW($I$13)+1),""))} -> 351280.46
A23: =IF(ENGINE!A12="","",ENGINE!A12) -> 10 | B23: =IF(A23="","",ENGINE!B12) -> 32 | C23: =IF(A23="","",ENGINE!D12) -> 13000 | D23: =IF(A23="","",INDEX('PERIODIC ENGINE'!$I$2:$I$102,MATCH(A23,'PERIODIC ENGINE'!$A$2:$A$102,0))) -> 17357.868 | E23: =IF(A23="","",'CHART DATA'!B12) -> 190936.55 | F23: =IF(A23="","",'CHART DATA'!C12) -> 106617.97 | G23: =IF(A23="","",INDEX('PERIODIC ENGINE'!$K$2:$K$102,MATCH(A23,'PERIODIC ENGINE'!$A$2:$A$102,0))) -> 109000 | H23: =IF(A23="","",E23-INPUTS!$C$8-G23) -> 81936.549 | I23: {=IF(A23="","",IFERROR(INDEX(TerminalValueByYear_Range,ROW()-ROW($I$13)+1),""))} -> 332119.71
A24: =IF(ENGINE!A13="","",ENGINE!A13) -> 11 | B24: =IF(A24="","",ENGINE!B13) -> 33 | C24: =IF(A24="","",ENGINE!D13) -> 14000 | D24: =IF(A24="","",INDEX('PERIODIC ENGINE'!$I$2:$I$102,MATCH(A24,'PERIODIC ENGINE'!$A$2:$A$102,0))) -> 20493.655 | E24: =IF(A24="","",'CHART DATA'!B13) -> 225430.2 | F24: =IF(A24="","",'CHART DATA'!C13) -> 118753.82 | G24: =IF(A24="","",INDEX('PERIODIC ENGINE'!$K$2:$K$102,MATCH(A24,'PERIODIC ENGINE'!$A$2:$A$102,0))) -> 123000 | H24: =IF(A24="","",E24-INPUTS!$C$8-G24) -> 102430.2 | I24: {=IF(A24="","",IFERROR(INDEX(TerminalValueByYear_Range,ROW()-ROW($I$13)+1),""))} -> 325152.16
... A113: =IF(ENGINE!A102="","",ENGINE!A102) | B113: =IF(A113="","",ENGINE!B102) | C113: =IF(A113="","",ENGINE!D102) | D113: =IF(A113="","",INDEX('PERIODIC ENGINE'!$I$2:$I$102,MATCH(A113,'PERIODIC ENGINE'!$A$2:$A$102,0))) | E113: =IF(A113="","",'CHART DATA'!B102) | F113: =IF(A113="","",'CHART DATA'!C102) | G113: =IF(A113="","",INDEX('PERIODIC ENGINE'!$K$2:$K$102,MATCH(A113,'PERIODIC ENGINE'!$A$2:$A$102,0))) | H113: =IF(A113="","",E113-INPUTS!$C$8-G113) | I113: {=IF(A113="","",IFERROR(INDEX(TerminalValueByYear_Range,ROW()-ROW($I$13)+1),""))}

Sheet OUTPUT - CASH FLOW
A1: Annual Cash Flow Detail
A2: Salary, federal and state income taxes, payroll taxes, Roth contributions, and disposable take-home pay.
A4: Annual Cash Flow Schedule
A6: Projection Year | B6: Age | C6: Gross Salary | D6: Federal Income Tax | E6: Flat State Income Tax | F6: Payroll Taxes | G6: Total Taxes | H6: Take-Home Pay After Taxes | I6: IRA Contribution | J6: Disposable Take-Home Pay
A7: =IF(ENGINE!A2="","",ENGINE!A2) -> 0 | B7: =IF(ENGINE!A2="","",ENGINE!B2) -> 22 | C7: =IF(ENGINE!A2="","",ENGINE!Y2) -> 70000 | D7: =IF(ENGINE!A2="","",ENGINE!AC2) -> 6570 | E7: =IF(ENGINE!A2="","",ENGINE!AD2) -> 0 | F7: =IF(ENGINE!A2="","",ENGINE!AG2) -> 5355 | G7: =IF(ENGINE!A2="","",ENGINE!AH2) -> 11925 | H7: =IF(ENGINE!A2="","",ENGINE!AI2) -> 58075 | I7: =IF(ENGINE!A2="","",ENGINE!D2) -> 7500 | J7: =IF(ENGINE!A2="","",ENGINE!AI2-ENGINE!D2) -> 50575
A8: =IF(ENGINE!A3="","",ENGINE!A3) -> 1 | B8: =IF(ENGINE!A3="","",ENGINE!B3) -> 23 | C8: =IF(ENGINE!A3="","",ENGINE!Y3) -> 74350 | D8: =IF(ENGINE!A3="","",ENGINE!AC3) -> 7057 | E8: =IF(ENGINE!A3="","",ENGINE!AD3) -> 0 | F8: =IF(ENGINE!A3="","",ENGINE!AG3) -> 5687.775 | G8: =IF(ENGINE!A3="","",ENGINE!AH3) -> 12744.775 | H8: =IF(ENGINE!A3="","",ENGINE!AI3) -> 61605.225 | I8: =IF(ENGINE!A3="","",ENGINE!D3) -> 7500 | J8: =IF(ENGINE!A3="","",ENGINE!AI3-ENGINE!D3) -> 54105.225
A9: =IF(ENGINE!A4="","",ENGINE!A4) -> 2 | B9: =IF(ENGINE!A4="","",ENGINE!B4) -> 24 | C9: =IF(ENGINE!A4="","",ENGINE!Y4) -> 78830.5 | D9: =IF(ENGINE!A4="","",ENGINE!AC4) -> 7545.71 | E9: =IF(ENGINE!A4="","",ENGINE!AD4) -> 0 | F9: =IF(ENGINE!A4="","",ENGINE!AG4) -> 6030.5333 | G9: =IF(ENGINE!A4="","",ENGINE!AH4) -> 13576.243 | H9: =IF(ENGINE!A4="","",ENGINE!AI4) -> 65254.257 | I9: =IF(ENGINE!A4="","",ENGINE!D4) -> 8000 | J9: =IF(ENGINE!A4="","",ENGINE!AI4-ENGINE!D4) -> 57254.257
A10: =IF(ENGINE!A5="","",ENGINE!A5) -> 3 | B10: =IF(ENGINE!A5="","",ENGINE!B5) -> 25 | C10: =IF(ENGINE!A5="","",ENGINE!Y5) -> 83445.415 | D10: =IF(ENGINE!A5="","",ENGINE!AC5) -> 8020.9913 | E10: =IF(ENGINE!A5="","",ENGINE!AD5) -> 0 | F10: =IF(ENGINE!A5="","",ENGINE!AG5) -> 6383.5742 | G10: =IF(ENGINE!A5="","",ENGINE!AH5) -> 14404.566 | H10: =IF(ENGINE!A5="","",ENGINE!AI5) -> 69040.849 | I10: =IF(ENGINE!A5="","",ENGINE!D5) -> 8500 | J10: =IF(ENGINE!A5="","",ENGINE!AI5-ENGINE!D5) -> 60540.849
A11: =IF(ENGINE!A6="","",ENGINE!A6) -> 4 | B11: =IF(ENGINE!A6="","",ENGINE!B6) -> 26 | C11: =IF(ENGINE!A6="","",ENGINE!Y6) -> 103198.78 | D11: =IF(ENGINE!A6="","",ENGINE!AC6) -> 11810.731 | E11: =IF(ENGINE!A6="","",ENGINE!AD6) -> 0 | F11: =IF(ENGINE!A6="","",ENGINE!AG6) -> 7894.7065 | G11: =IF(ENGINE!A6="","",ENGINE!AH6) -> 19705.438 | H11: =IF(ENGINE!A6="","",ENGINE!AI6) -> 83493.34 | I11: =IF(ENGINE!A6="","",ENGINE!D6) -> 9000 | J11: =IF(ENGINE!A6="","",ENGINE!AI6-ENGINE!D6) -> 74493.34
A12: =IF(ENGINE!A7="","",ENGINE!A7) -> 5 | B12: =IF(ENGINE!A7="","",ENGINE!B7) -> 27 | C12: =IF(ENGINE!A7="","",ENGINE!Y7) -> 106294.74 | D12: =IF(ENGINE!A7="","",ENGINE!AC7) -> 7088.3689 | E12: =IF(ENGINE!A7="","",ENGINE!AD7) -> 0 | F12: =IF(ENGINE!A7="","",ENGINE!AG7) -> 8131.5477 | G12: =IF(ENGINE!A7="","",ENGINE!AH7) -> 15219.917 | H12: =IF(ENGINE!A7="","",ENGINE!AI7) -> 91074.824 | I12: =IF(ENGINE!A7="","",ENGINE!D7) -> 10000 | J12: =IF(ENGINE!A7="","",ENGINE!AI7-ENGINE!D7) -> 81074.824
A13: =IF(ENGINE!A8="","",ENGINE!A8) -> 6 | B13: =IF(ENGINE!A8="","",ENGINE!B8) -> 28 | C13: =IF(ENGINE!A8="","",ENGINE!Y8) -> 109483.58 | D13: =IF(ENGINE!A8="","",ENGINE!AC8) -> 7160.03 | E13: =IF(ENGINE!A8="","",ENGINE!AD8) -> 0 | F13: =IF(ENGINE!A8="","",ENGINE!AG8) -> 8375.4941 | G13: =IF(ENGINE!A8="","",ENGINE!AH8) -> 15535.524 | H13: =IF(ENGINE!A8="","",ENGINE!AI8) -> 93948.059 | I13: =IF(ENGINE!A8="","",ENGINE!D8) -> 10500 | J13: =IF(ENGINE!A8="","",ENGINE!AI8-ENGINE!D8) -> 83448.059
A14: =IF(ENGINE!A9="","",ENGINE!A9) -> 7 | B14: =IF(ENGINE!A9="","",ENGINE!B9) -> 29 | C14: =IF(ENGINE!A9="","",ENGINE!Y9) -> 112768.09 | D14: =IF(ENGINE!A9="","",ENGINE!AC9) -> 7235.1709 | E14: =IF(ENGINE!A9="","",ENGINE!AD9) -> 0 | F14: =IF(ENGINE!A9="","",ENGINE!AG9) -> 8626.7589 | G14: =IF(ENGINE!A9="","",ENGINE!AH9) -> 15861.93 | H14: =IF(ENGINE!A9="","",ENGINE!AI9) -> 96906.161 | I14: =IF(ENGINE!A9="","",ENGINE!D9) -> 11000 | J14: =IF(ENGINE!A9="","",ENGINE!AI9-ENGINE!D9) -> 85906.161
A15: =IF(ENGINE!A10="","",ENGINE!A10) -> 8 | B15: =IF(ENGINE!A10="","",ENGINE!B10) -> 30 | C15: =IF(ENGINE!A10="","",ENGINE!Y10) -> 116151.13 | D15: =IF(ENGINE!A10="","",ENGINE!AC10) -> 7297.136 | E15: =IF(ENGINE!A10="","",ENGINE!AD10) -> 0 | F15: =IF(ENGINE!A10="","",ENGINE!AG10) -> 8885.5617 | G15: =IF(ENGINE!A10="","",ENGINE!AH10) -> 16182.698 | H15: =IF(ENGINE!A10="","",ENGINE!AI10) -> 99968.436 | I15: =IF(ENGINE!A10="","",ENGINE!D10) -> 11500 | J15: =IF(ENGINE!A10="","",ENGINE!AI10-ENGINE!D10) -> 88468.436
A16: =IF(ENGINE!A11="","",ENGINE!A11) -> 9 | B16: =IF(ENGINE!A11="","",ENGINE!B11) -> 31 | C16: =IF(ENGINE!A11="","",ENGINE!Y11) -> 119635.67 | D16: =IF(ENGINE!A11="","",ENGINE!AC11) -> 7356.2801 | E16: =IF(ENGINE!A11="","",ENGINE!AD11) -> 0 | F16: =IF(ENGINE!A11="","",ENGINE!AG11) -> 9152.1285 | G16: =IF(ENGINE!A11="","",ENGINE!AH11) -> 16508.409 | H16: =IF(ENGINE!A11="","",ENGINE!AI11) -> 103127.26 | I16: =IF(ENGINE!A11="","",ENGINE!D11) -> 12500 | J16: =IF(ENGINE!A11="","",ENGINE!AI11-ENGINE!D11) -> 90627.259
A17: =IF(ENGINE!A12="","",ENGINE!A12) -> 10 | B17: =IF(ENGINE!A12="","",ENGINE!B12) -> 32 | C17: =IF(ENGINE!A12="","",ENGINE!Y12) -> 123224.74 | D17: =IF(ENGINE!A12="","",ENGINE!AC12) -> 7407.9685 | E17: =IF(ENGINE!A12="","",ENGINE!AD12) -> 0 | F17: =IF(ENGINE!A12="","",ENGINE!AG12) -> 9426.6924 | G17: =IF(ENGINE!A12="","",ENGINE!AH12) -> 16834.661 | H17: =IF(ENGINE!A12="","",ENGINE!AI12) -> 106390.08 | I17: =IF(ENGINE!A12="","",ENGINE!D12) -> 13000 | J17: =IF(ENGINE!A12="","",ENGINE!AI12-ENGINE!D12) -> 93390.076
A18: =IF(ENGINE!A13="","",ENGINE!A13) -> 11 | B18: =IF(ENGINE!A13="","",ENGINE!B13) -> 33 | C18: =IF(ENGINE!A13="","",ENGINE!Y13) -> 126921.48 | D18: =IF(ENGINE!A13="","",ENGINE!AC13) -> 7451.5775 | E18: =IF(ENGINE!A13="","",ENGINE!AD13) -> 0 | F18: =IF(ENGINE!A13="","",ENGINE!AG13) -> 9709.4932 | G18: =IF(ENGINE!A13="","",ENGINE!AH13) -> 17161.071 | H18: =IF(ENGINE!A13="","",ENGINE!AI13) -> 109760.41 | I18: =IF(ENGINE!A13="","",ENGINE!D13) -> 14000 | J18: =IF(ENGINE!A13="","",ENGINE!AI13-ENGINE!D13) -> 95760.409
... A24: =IF(ENGINE!A19="","",ENGINE!A19) -> 17 | B24: =IF(ENGINE!A19="","",ENGINE!B19) -> 39 | C24: =IF(ENGINE!A19="","",ENGINE!Y19) -> 151550.88 | D24: =IF(ENGINE!A19="","",ENGINE!AC19) -> 7517.1061 | E24: =IF(ENGINE!A19="","",ENGINE!AD19) -> 0 | F24: =IF(ENGINE!A19="","",ENGINE!AG19) -> 11593.643 | G24: =IF(ENGINE!A19="","",ENGINE!AH19) -> 19110.749 | H24: =IF(ENGINE!A19="","",ENGINE!AI19) -> 132440.14 | I24: =IF(ENGINE!A19="","",ENGINE!D19) -> 20000 | J24: =IF(ENGINE!A19="","",ENGINE!AI19-ENGINE!D19) -> 112440.14
A25: =IF(ENGINE!A20="","",ENGINE!A20) -> 18 | B25: =IF(ENGINE!A20="","",ENGINE!B20) -> 40 | C25: =IF(ENGINE!A20="","",ENGINE!Y20) -> 156097.41 | D25: =IF(ENGINE!A20="","",ENGINE!AC20) -> 7486.6892 | E25: =IF(ENGINE!A20="","",ENGINE!AD20) -> 0 | F25: =IF(ENGINE!A20="","",ENGINE!AG20) -> 11941.452 | G25: =IF(ENGINE!A20="","",ENGINE!AH20) -> 19428.141 | H25: =IF(ENGINE!A20="","",ENGINE!AI20) -> 136669.27 | I25: =IF(ENGINE!A20="","",ENGINE!D20) -> 21000 | J25: =IF(ENGINE!A20="","",ENGINE!AI20-ENGINE!D20) -> 115669.27 | L25: Cumulative Tax Summary
A26: =IF(ENGINE!A21="","",ENGINE!A21) -> 19 | B26: =IF(ENGINE!A21="","",ENGINE!B21) -> 41 | C26: =IF(ENGINE!A21="","",ENGINE!Y21) -> 160780.33 | D26: =IF(ENGINE!A21="","",ENGINE!AC21) -> 7439.6399 | E26: =IF(ENGINE!A21="","",ENGINE!AD21) -> 0 | F26: =IF(ENGINE!A21="","",ENGINE!AG21) -> 12299.695 | G26: =IF(ENGINE!A21="","",ENGINE!AH21) -> 19739.335 | H26: =IF(ENGINE!A21="","",ENGINE!AI21) -> 141041 | I26: =IF(ENGINE!A21="","",ENGINE!D21) -> 22500 | J26: =IF(ENGINE!A21="","",ENGINE!AI21-ENGINE!D21) -> 118541
A27: =IF(ENGINE!A22="","",ENGINE!A22) -> 20 | B27: =IF(ENGINE!A22="","",ENGINE!B22) -> 42 | C27: =IF(ENGINE!A22="","",ENGINE!Y22) -> 165603.74 | D27: =IF(ENGINE!A22="","",ENGINE!AC22) -> 7381.4491 | E27: =IF(ENGINE!A22="","",ENGINE!AD22) -> 0 | F27: =IF(ENGINE!A22="","",ENGINE!AG22) -> 12668.686 | G27: =IF(ENGINE!A22="","",ENGINE!AH22) -> 20050.135 | H27: =IF(ENGINE!A22="","",ENGINE!AI22) -> 145553.61 | I27: =IF(ENGINE!A22="","",ENGINE!D22) -> 24000 | J27: =IF(ENGINE!A22="","",ENGINE!AI22-ENGINE!D22) -> 121553.61 | L27: Federal income tax | M27: =SUM(ENGINE!AC2:AC102) -> 288998.75
A28: =IF(ENGINE!A23="","",ENGINE!A23) -> 21 | B28: =IF(ENGINE!A23="","",ENGINE!B23) -> 43 | C28: =IF(ENGINE!A23="","",ENGINE!Y23) -> 170571.85 | D28: =IF(ENGINE!A23="","",ENGINE!AC23) -> 7332.1855 | E28: =IF(ENGINE!A23="","",ENGINE!AD23) -> 0 | F28: =IF(ENGINE!A23="","",ENGINE!AG23) -> 13048.747 | G28: =IF(ENGINE!A23="","",ENGINE!AH23) -> 20380.932 | H28: =IF(ENGINE!A23="","",ENGINE!AI23) -> 150190.92 | I28: =IF(ENGINE!A23="","",ENGINE!D23) -> 25000 | J28: =IF(ENGINE!A23="","",ENGINE!AI23-ENGINE!D23) -> 125190.92 | L28: Flat state income tax | M28: =SUM(ENGINE!AD2:AD102) -> 0
A29: =IF(ENGINE!A24="","",ENGINE!A24) -> 22 | B29: =IF(ENGINE!A24="","",ENGINE!B24) -> 44 | C29: =IF(ENGINE!A24="","",ENGINE!Y24) -> 175689.01 | D29: =IF(ENGINE!A24="","",ENGINE!AC24) -> 7318.9011 | E29: =IF(ENGINE!A24="","",ENGINE!AD24) -> 0 | F29: =IF(ENGINE!A24="","",ENGINE!AG24) -> 13440.209 | G29: =IF(ENGINE!A24="","",ENGINE!AH24) -> 20759.11 | H29: =IF(ENGINE!A24="","",ENGINE!AI24) -> 154929.9 | I29: =IF(ENGINE!A24="","",ENGINE!D24) -> 27000 | J29: =IF(ENGINE!A24="","",ENGINE!AI24-ENGINE!D24) -> 127929.9 | L29: Payroll taxes | M29: =SUM(ENGINE!AG2:AG102) -> 622072.03
A30: =IF(ENGINE!A25="","",ENGINE!A25) -> 23 | B30: =IF(ENGINE!A25="","",ENGINE!B25) -> 45 | C30: =IF(ENGINE!A25="","",ENGINE!Y25) -> 180959.68 | D30: =IF(ENGINE!A25="","",ENGINE!AC25) -> 7290.9681 | E30: =IF(ENGINE!A25="","",ENGINE!AD25) -> 0 | F30: =IF(ENGINE!A25="","",ENGINE!AG25) -> 13843.416 | G30: =IF(ENGINE!A25="","",ENGINE!AH25) -> 21134.384 | H30: =IF(ENGINE!A25="","",ENGINE!AI25) -> 159825.3 | I30: =IF(ENGINE!A25="","",ENGINE!D25) -> 28500 | J30: =IF(ENGINE!A25="","",ENGINE!AI25-ENGINE!D25) -> 131325.3 | L30: Total taxes paid | M30: =SUM(ENGINE!AH2:AH102) -> 911070.78
A31: =IF(ENGINE!A26="","",ENGINE!A26) -> 24 | B31: =IF(ENGINE!A26="","",ENGINE!B26) -> 46 | C31: =IF(ENGINE!A26="","",ENGINE!Y26) -> 186388.47 | D31: =IF(ENGINE!A26="","",ENGINE!AC26) -> 7248.8471 | E31: =IF(ENGINE!A26="","",ENGINE!AD26) -> 0 | F31: =IF(ENGINE!A26="","",ENGINE!AG26) -> 14258.718 | G31: =IF(ENGINE!A26="","",ENGINE!AH26) -> 21507.565 | H31: =IF(ENGINE!A26="","",ENGINE!AI26) -> 164880.91 | I31: =IF(ENGINE!A26="","",ENGINE!D26) -> 30000 | J31: =IF(ENGINE!A26="","",ENGINE!AI26-ENGINE!D26) -> 134880.91 | L31: Total gross income earned | M31: =SUM(ENGINE!Y2:Y102) -> 8087943.7
A32: =IF(ENGINE!A27="","",ENGINE!A27) -> 25 | B32: =IF(ENGINE!A27="","",ENGINE!B27) -> 47 | C32: =IF(ENGINE!A27="","",ENGINE!Y27) -> 191980.13 | D32: =IF(ENGINE!A27="","",ENGINE!AC27) -> 7193.0125 | E32: =IF(ENGINE!A27="","",ENGINE!AD27) -> 0 | F32: =IF(ENGINE!A27="","",ENGINE!AG27) -> 14686.48 | G32: =IF(ENGINE!A27="","",ENGINE!AH27) -> 21879.492 | H32: =IF(ENGINE!A27="","",ENGINE!AI27) -> 170100.63 | I32: =IF(ENGINE!A27="","",ENGINE!D27) -> 32000 | J32: =IF(ENGINE!A27="","",ENGINE!AI27-ENGINE!D27) -> 138100.63 | L32: Cumulative Total Tax Rate | M32: =IFERROR(M30/M31,0) -> 0.11264554
A33: =IF(ENGINE!A28="","",ENGINE!A28) -> 26 | B33: =IF(ENGINE!A28="","",ENGINE!B28) -> 48 | C33: =IF(ENGINE!A28="","",ENGINE!Y28) -> 197739.53 | D33: =IF(ENGINE!A28="","",ENGINE!AC28) -> 7118.9529 | E33: =IF(ENGINE!A28="","",ENGINE!AD28) -> 0 | F33: =IF(ENGINE!A28="","",ENGINE!AG28) -> 15127.074 | G33: =IF(ENGINE!A28="","",ENGINE!AH28) -> 22246.027 | H33: =IF(ENGINE!A28="","",ENGINE!AI28) -> 175493.5 | I33: =IF(ENGINE!A28="","",ENGINE!D28) -> 34000 | J33: =IF(ENGINE!A28="","",ENGINE!AI28-ENGINE!D28) -> 141493.5 | L33: Cumulative effective take-home rate | M33: =1-M32 -> 0.88735446
A34: =IF(ENGINE!A29="","",ENGINE!A29) -> 27 | B34: =IF(ENGINE!A29="","",ENGINE!B29) -> 49 | C34: =IF(ENGINE!A29="","",ENGINE!Y29) -> 203671.72 | D34: =IF(ENGINE!A29="","",ENGINE!AC29) -> 7027.1715 | E34: =IF(ENGINE!A29="","",ENGINE!AD29) -> 0 | F34: =IF(ENGINE!A29="","",ENGINE!AG29) -> 15580.886 | G34: =IF(ENGINE!A29="","",ENGINE!AH29) -> 22608.058 | H34: =IF(ENGINE!A29="","",ENGINE!AI29) -> 181063.66 | I34: =IF(ENGINE!A29="","",ENGINE!D29) -> 36000 | J34: =IF(ENGINE!A29="","",ENGINE!AI29-ENGINE!D29) -> 145063.66
A35: =IF(ENGINE!A30="","",ENGINE!A30) -> 28 | B35: =IF(ENGINE!A30="","",ENGINE!B30) -> 50 | C35: =IF(ENGINE!A30="","",ENGINE!Y30) -> 209781.87 | D35: =IF(ENGINE!A30="","",ENGINE!AC30) -> 6918.1867 | E35: =IF(ENGINE!A30="","",ENGINE!AD30) -> 0 | F35: =IF(ENGINE!A30="","",ENGINE!AG30) -> 16048.313 | G35: =IF(ENGINE!A30="","",ENGINE!AH30) -> 22966.499 | H35: =IF(ENGINE!A30="","",ENGINE!AI30) -> 186815.37 | I35: =IF(ENGINE!A30="","",ENGINE!D30) -> 43600 | J35: =IF(ENGINE!A30="","",ENGINE!AI30-ENGINE!D30) -> 143215.37
A36: =IF(ENGINE!A31="","",ENGINE!A31) -> 29 | B36: =IF(ENGINE!A31="","",ENGINE!B31) -> 51 | C36: =IF(ENGINE!A31="","",ENGINE!Y31) -> 216075.32 | D36: =IF(ENGINE!A31="","",ENGINE!AC31) -> 6787.5323 | E36: =IF(ENGINE!A31="","",ENGINE!AD31) -> 0 | F36: =IF(ENGINE!A31="","",ENGINE!AG31) -> 16529.762 | G36: =IF(ENGINE!A31="","",ENGINE!AH31) -> 23317.294 | H36: =IF(ENGINE!A31="","",ENGINE!AI31) -> 192758.03 | I36: =IF(ENGINE!A31="","",ENGINE!D31) -> 46400 | J36: =IF(ENGINE!A31="","",ENGINE!AI31-ENGINE!D31) -> 146358.03
A37: =IF(ENGINE!A32="","",ENGINE!A32) -> 30 | B37: =IF(ENGINE!A32="","",ENGINE!B32) -> 52 | C37: =IF(ENGINE!A32="","",ENGINE!Y32) -> 222557.58 | D37: =IF(ENGINE!A32="","",ENGINE!AC32) -> 6635.7582 | E37: =IF(ENGINE!A32="","",ENGINE!AD32) -> 0 | F37: =IF(ENGINE!A32="","",ENGINE!AG32) -> 17025.655 | G37: =IF(ENGINE!A32="","",ENGINE!AH32) -> 23661.413 | H37: =IF(ENGINE!A32="","",ENGINE!AI32) -> 198896.17 | I37: =IF(ENGINE!A32="","",ENGINE!D32) -> 49300 | J37: =IF(ENGINE!A32="","",ENGINE!AI32-ENGINE!D32) -> 149596.17
A38: =IF(ENGINE!A33="","",ENGINE!A33) -> 31 | B38: =IF(ENGINE!A33="","",ENGINE!B33) -> 53 | C38: =IF(ENGINE!A33="","",ENGINE!Y33) -> 229234.31 | D38: =IF(ENGINE!A33="","",ENGINE!AC33) -> 6458.431 | E38: =IF(ENGINE!A33="","",ENGINE!AD33) -> 0 | F38: =IF(ENGINE!A33="","",ENGINE!AG33) -> 17536.425 | G38: =IF(ENGINE!A33="","",ENGINE!AH33) -> 23994.856 | H38: =IF(ENGINE!A33="","",ENGINE!AI33) -> 205239.45 | I38: =IF(ENGINE!A33="","",ENGINE!D33) -> 52100 | J38: =IF(ENGINE!A33="","",ENGINE!AI33-ENGINE!D33) -> 153139.45
A39: =IF(ENGINE!A34="","",ENGINE!A34) -> 32 | B39: =IF(ENGINE!A34="","",ENGINE!B34) -> 54 | C39: =IF(ENGINE!A34="","",ENGINE!Y34) -> 236111.34 | D39: =IF(ENGINE!A34="","",ENGINE!AC34) -> 6256.1339 | E39: =IF(ENGINE!A34="","",ENGINE!AD34) -> 0 | F39: =IF(ENGINE!A34="","",ENGINE!AG34) -> 18062.517 | G39: =IF(ENGINE!A34="","",ENGINE!AH34) -> 24318.651 | H39: =IF(ENGINE!A34="","",ENGINE!AI34) -> 211792.69 | I39: =IF(ENGINE!A34="","",ENGINE!D34) -> 55000 | J39: =IF(ENGINE!A34="","",ENGINE!AI34-ENGINE!D34) -> 156792.69
A40: =IF(ENGINE!A35="","",ENGINE!A35) -> 33 | B40: =IF(ENGINE!A35="","",ENGINE!B35) -> 55 | C40: =IF(ENGINE!A35="","",ENGINE!Y35) -> 243194.68 | D40: =IF(ENGINE!A35="","",ENGINE!AC35) -> 6024.4679 | E40: =IF(ENGINE!A35="","",ENGINE!AD35) -> 0 | F40: =IF(ENGINE!A35="","",ENGINE!AG35) -> 18604.393 | G40: =IF(ENGINE!A35="","",ENGINE!AH35) -> 24628.861 | H40: =IF(ENGINE!A35="","",ENGINE!AI35) -> 218565.82 | I40: =IF(ENGINE!A35="","",ENGINE!D35) -> 58500 | J40: =IF(ENGINE!A35="","",ENGINE!AI35-ENGINE!D35) -> 160065.82
A41: =IF(ENGINE!A36="","",ENGINE!A36) -> 34 | B41: =IF(ENGINE!A36="","",ENGINE!B36) -> 56 | C41: =IF(ENGINE!A36="","",ENGINE!Y36) -> 250490.52 | D41: =IF(ENGINE!A36="","",ENGINE!AC36) -> 5764.052 | E41: =IF(ENGINE!A36="","",ENGINE!AD36) -> 0 | F41: =IF(ENGINE!A36="","",ENGINE!AG36) -> 19166.939 | G41: =IF(ENGINE!A36="","",ENGINE!AH36) -> 24930.991 | H41: =IF(ENGINE!A36="","",ENGINE!AI36) -> 225559.53 | I41: =IF(ENGINE!A36="","",ENGINE!D36) -> 61900 | J41: =IF(ENGINE!A36="","",ENGINE!AI36-ENGINE!D36) -> 163659.53
A42: =IF(ENGINE!A37="","",ENGINE!A37) -> 35 | B42: =IF(ENGINE!A37="","",ENGINE!B37) -> 57 | C42: =IF(ENGINE!A37="","",ENGINE!Y37) -> 258005.24 | D42: =IF(ENGINE!A37="","",ENGINE!AC37) -> 5470.5235 | E42: =IF(ENGINE!A37="","",ENGINE!AD37) -> 0 | F42: =IF(ENGINE!A37="","",ENGINE!AG37) -> 19809.448 | G42: =IF(ENGINE!A37="","",ENGINE!AH37) -> 25279.971 | H42: =IF(ENGINE!A37="","",ENGINE!AI37) -> 232725.26 | I42: =IF(ENGINE!A37="","",ENGINE!D37) -> 65900 | J42: =IF(ENGINE!A37="","",ENGINE!AI37-ENGINE!D37) -> 166825.26
A43: =IF(ENGINE!A38="","",ENGINE!A38) -> 36 | B43: =IF(ENGINE!A38="","",ENGINE!B38) -> 58 | C43: =IF(ENGINE!A38="","",ENGINE!Y38) -> 265745.39 | D43: =IF(ENGINE!A38="","",ENGINE!AC38) -> 5149.5392 | E43: =IF(ENGINE!A38="","",ENGINE!AD38) -> 0 | F43: =IF(ENGINE!A38="","",ENGINE!AG38) -> 20471.231 | G43: =IF(ENGINE!A38="","",ENGINE!AH38) -> 25620.77 | H43: =IF(ENGINE!A38="","",ENGINE!AI38) -> 240124.62 | I43: =IF(ENGINE!A38="","",ENGINE!D38) -> 69900 | J43: =IF(ENGINE!A38="","",ENGINE!AI38-ENGINE!D38) -> 170224.62
A44: =IF(ENGINE!A39="","",ENGINE!A39) -> 37 | B44: =IF(ENGINE!A39="","",ENGINE!B39) -> 59 | C44: =IF(ENGINE!A39="","",ENGINE!Y39) -> 273717.75 | D44: =IF(ENGINE!A39="","",ENGINE!AC39) -> 4786.7754 | E44: =IF(ENGINE!A39="","",ENGINE!AD39) -> 0 | F44: =IF(ENGINE!A39="","",ENGINE!AG39) -> 21152.868 | G44: =IF(ENGINE!A39="","",ENGINE!AH39) -> 25939.643 | H44: =IF(ENGINE!A39="","",ENGINE!AI39) -> 247778.11 | I44: =IF(ENGINE!A39="","",ENGINE!D39) -> 73900 | J44: =IF(ENGINE!A39="","",ENGINE!AI39-ENGINE!D39) -> 173878.11
A45: =IF(ENGINE!A40="","",ENGINE!A40) -> 38 | B45: =IF(ENGINE!A40="","",ENGINE!B40) -> 60 | C45: =IF(ENGINE!A40="","",ENGINE!Y40) -> 281929.29 | D45: =IF(ENGINE!A40="","",ENGINE!AC40) -> 4387.9287 | E45: =IF(ENGINE!A40="","",ENGINE!AD40) -> 0 | F45: =IF(ENGINE!A40="","",ENGINE!AG40) -> 21854.954 | G45: =IF(ENGINE!A40="","",ENGINE!AH40) -> 26242.883 | H45: =IF(ENGINE!A40="","",ENGINE!AI40) -> 255686.4 | I45: =IF(ENGINE!A40="","",ENGINE!D40) -> 78500 | J45: =IF(ENGINE!A40="","",ENGINE!AI40-ENGINE!D40) -> 177186.4
... A107: =IF(ENGINE!A102="","",ENGINE!A102) | B107: =IF(ENGINE!A102="","",ENGINE!B102) | C107: =IF(ENGINE!A102="","",ENGINE!Y102) | D107: =IF(ENGINE!A102="","",ENGINE!AC102) | E107: =IF(ENGINE!A102="","",ENGINE!AD102) | F107: =IF(ENGINE!A102="","",ENGINE!AG102) | G107: =IF(ENGINE!A102="","",ENGINE!AH102) | H107: =IF(ENGINE!A102="","",ENGINE!AI102) | I107: =IF(ENGINE!A102="","",ENGINE!D102) | J107: =IF(ENGINE!A102="","",ENGINE!AI102-ENGINE!D102)

Sheet MILESTONES
A1: Retirement Balance Milestones
A2: How long until you cross each balance threshold
A4: Milestone | B4: Threshold | C4: Years to Milestone | D4: Age | E4: Nominal Balance | F4: Real Balance | G4: Cumulative Contributions | H4: Cumulative Investment Growth | J4: First Projection Year (Helper)
A5: First $500,000 | B5: 500000 | C5: =IF($J5="Not reached","Not reached",$J5) -> 17 | D5: =IF($J5="Not reached","Not reached",INDEX(ENGINE!$B$2:$B$102,MATCH($J5,ENGINE!$A$2:$A$102,0))) -> 39 | E5: =IF($J5="Not reached","Not reached",INDEX(ENGINE!$L$2:$L$102,MATCH($J5,ENGINE!$A$2:$A$102,0))) -> 543339.83 | F5: =IF($J5="Not reached","Not reached",INDEX(ENGINE!$N$2:$N$102,MATCH($J5,ENGINE!$A$2:$A$102,0))) -> 201777.08 | G5: =IF($J5="Not reached","Not reached",INDEX(ENGINE!$O$2:$O$102,MATCH($J5,ENGINE!$A$2:$A$102,0))) -> 226500 | H5: =IF($J5="Not reached","Not reached",INDEX(ENGINE!$P$2:$P$102,MATCH($J5,ENGINE!$A$2:$A$102,0))) -> 316839.83 | J5: {=IFERROR(INDEX(ENGINE!$A$2:$A$102,_xlfn.AGGREGATE(15,6,(ROW(ENGINE!$L$2:$L$102)-ROW(ENGINE!$L$2)+1)/((ENGINE!$L$2:$L$102>=$B5)*(ENGINE!$A$2:$A$102<>"")),1)),"Not reached")} -> 17
A6: First $1,000,000 | B6: 1000000 | C6: =IF($J6="Not reached","Not reached",$J6) -> 22 | D6: =IF($J6="Not reached","Not reached",INDEX(ENGINE!$B$2:$B$102,MATCH($J6,ENGINE!$A$2:$A$102,0))) -> 44 | E6: =IF($J6="Not reached","Not reached",INDEX(ENGINE!$L$2:$L$102,MATCH($J6,ENGINE!$A$2:$A$102,0))) -> 1033711.2 | F6: =IF($J6="Not reached","Not reached",INDEX(ENGINE!$N$2:$N$102,MATCH($J6,ENGINE!$A$2:$A$102,0))) -> 286860.12 | G6: =IF($J6="Not reached","Not reached",INDEX(ENGINE!$O$2:$O$102,MATCH($J6,ENGINE!$A$2:$A$102,0))) -> 346000 | H6: =IF($J6="Not reached","Not reached",INDEX(ENGINE!$P$2:$P$102,MATCH($J6,ENGINE!$A$2:$A$102,0))) -> 687711.19 | J6: {=IFERROR(INDEX(ENGINE!$A$2:$A$102,_xlfn.AGGREGATE(15,6,(ROW(ENGINE!$L$2:$L$102)-ROW(ENGINE!$L$2)+1)/((ENGINE!$L$2:$L$102>=$B6)*(ENGINE!$A$2:$A$102<>"")),1)),"Not reached")} -> 22
A7: First $2,000,000 | B7: 2000000 | C7: =IF($J7="Not reached","Not reached",$J7) -> 28 | D7: =IF($J7="Not reached","Not reached",INDEX(ENGINE!$B$2:$B$102,MATCH($J7,ENGINE!$A$2:$A$102,0))) -> 50 | E7: =IF($J7="Not reached","Not reached",INDEX(ENGINE!$L$2:$L$102,MATCH($J7,ENGINE!$A$2:$A$102,0))) -> 2113712.4 | F7: =IF($J7="Not reached","Not reached",INDEX(ENGINE!$N$2:$N$102,MATCH($J7,ENGINE!$A$2:$A$102,0))) -> 413505.86 | G7: =IF($J7="Not reached","Not reached",INDEX(ENGINE!$O$2:$O$102,MATCH($J7,ENGINE!$A$2:$A$102,0))) -> 550100 | H7: =IF($J7="Not reached","Not reached",INDEX(ENGINE!$P$2:$P$102,MATCH($J7,ENGINE!$A$2:$A$102,0))) -> 1563612.4 | J7: {=IFERROR(INDEX(ENGINE!$A$2:$A$102,_xlfn.AGGREGATE(15,6,(ROW(ENGINE!$L$2:$L$102)-ROW(ENGINE!$L$2)+1)/((ENGINE!$L$2:$L$102>=$B7)*(ENGINE!$A$2:$A$102<>"")),1)),"Not reached")} -> 28
A8: First $5,000,000 | B8: 5000000 | C8: =IF($J8="Not reached","Not reached",$J8) -> 36 | D8: =IF($J8="Not reached","Not reached",INDEX(ENGINE!$B$2:$B$102,MATCH($J8,ENGINE!$A$2:$A$102,0))) -> 58 | E8: =IF($J8="Not reached","Not reached",INDEX(ENGINE!$L$2:$L$102,MATCH($J8,ENGINE!$A$2:$A$102,0))) -> 5232008.7 | F8: =IF($J8="Not reached","Not reached",INDEX(ENGINE!$N$2:$N$102,MATCH($J8,ENGINE!$A$2:$A$102,0))) -> 642180.78 | G8: =IF($J8="Not reached","Not reached",INDEX(ENGINE!$O$2:$O$102,MATCH($J8,ENGINE!$A$2:$A$102,0))) -> 1009100 | H8: =IF($J8="Not reached","Not reached",INDEX(ENGINE!$P$2:$P$102,MATCH($J8,ENGINE!$A$2:$A$102,0))) -> 4222908.7 | J8: {=IFERROR(INDEX(ENGINE!$A$2:$A$102,_xlfn.AGGREGATE(15,6,(ROW(ENGINE!$L$2:$L$102)-ROW(ENGINE!$L$2)+1)/((ENGINE!$L$2:$L$102>=$B8)*(ENGINE!$A$2:$A$102<>"")),1)),"Not reached")} -> 36
A10: Each milestone uses the first projection year in which the modeled value is greater than or equal to the selected threshold.
A13: Career & Cash-Flow Milestones
A15: Metric | B15: Threshold | C15: Years to Milestone | D15: Age | E15: Value at Milestone | F15: Roth Contribution | G15: Disposable Take-Home Pay | H15: Cumulative Total Tax Rate | J15: First Projection Year (Helper)
A16: Gross Salary | B16: 100000 | C16: =IF($J16="Not reached","Not reached",$J16) -> 4 | D16: =IF($J16="Not reached","Not reached",INDEX(ENGINE!$B$2:$B$102,MATCH($J16,ENGINE!$A$2:$A$102,0))) -> 26 | E16: =IF($J16="Not reached","Not reached",INDEX(ENGINE!$Y$2:$Y$102,MATCH($J16,ENGINE!$A$2:$A$102,0))) -> 103198.78 | F16: =IF($J16="Not reached","Not reached",INDEX(ENGINE!$D$2:$D$102,MATCH($J16,ENGINE!$A$2:$A$102,0))) -> 9000 | G16: =IF($J16="Not reached","Not reached",INDEX(ENGINE!$AI$2:$AI$102,MATCH($J16,ENGINE!$A$2:$A$102,0))-INDEX(ENGINE!$D$2:$D$102,MATCH($J16,ENGINE!$A$2:$A$102,0))) -> 74493.34 | H16: =IF($J16="Not reached","Not reached",IFERROR(SUMIFS(ENGINE!$AH$2:$AH$102,ENGINE!$A$2:$A$102,"<="&$J16)/SUMIFS(ENGINE!$Y$2:$Y$102,ENGINE!$A$2:$A$102,"<="&$J16),0)) -> 0.17655359 | J16: {=IFERROR(INDEX(ENGINE!$A$2:$A$102,_xlfn.AGGREGATE(15,6,(ROW(ENGINE!$A$2:$A$102)-ROW(ENGINE!$A$2)+1)/((ENGINE!$Y$2:$Y$102>=$B16)*(ENGINE!$A$2:$A$102<>"")),1)),"Not reached")} -> 4
A17: Gross Salary | B17: 250000 | C17: =IF($J17="Not reached","Not reached",$J17) -> 34 | D17: =IF($J17="Not reached","Not reached",INDEX(ENGINE!$B$2:$B$102,MATCH($J17,ENGINE!$A$2:$A$102,0))) -> 56 | E17: =IF($J17="Not reached","Not reached",INDEX(ENGINE!$Y$2:$Y$102,MATCH($J17,ENGINE!$A$2:$A$102,0))) -> 250490.52 | F17: =IF($J17="Not reached","Not reached",INDEX(ENGINE!$D$2:$D$102,MATCH($J17,ENGINE!$A$2:$A$102,0))) -> 61900 | G17: =IF($J17="Not reached","Not reached",INDEX(ENGINE!$AI$2:$AI$102,MATCH($J17,ENGINE!$A$2:$A$102,0))-INDEX(ENGINE!$D$2:$D$102,MATCH($J17,ENGINE!$A$2:$A$102,0))) -> 163659.53 | H17: =IF($J17="Not reached","Not reached",IFERROR(SUMIFS(ENGINE!$AH$2:$AH$102,ENGINE!$A$2:$A$102,"<="&$J17)/SUMIFS(ENGINE!$Y$2:$Y$102,ENGINE!$A$2:$A$102,"<="&$J17),0)) -> 0.12311337 | J17: {=IFERROR(INDEX(ENGINE!$A$2:$A$102,_xlfn.AGGREGATE(15,6,(ROW(ENGINE!$A$2:$A$102)-ROW(ENGINE!$A$2)+1)/((ENGINE!$Y$2:$Y$102>=$B17)*(ENGINE!$A$2:$A$102<>"")),1)),"Not reached")} -> 34
A18: Disposable Take-Home Pay | B18: 100000 | C18: =IF($J18="Not reached","Not reached",$J18) -> 13 | D18: =IF($J18="Not reached","Not reached",INDEX(ENGINE!$B$2:$B$102,MATCH($J18,ENGINE!$A$2:$A$102,0))) -> 35 | E18: =IF($J18="Not reached","Not reached",INDEX(ENGINE!$AI$2:$AI$102,MATCH($J18,ENGINE!$A$2:$A$102,0))-INDEX(ENGINE!$D$2:$D$102,MATCH($J18,ENGINE!$A$2:$A$102,0))) -> 101331.08 | F18: =IF($J18="Not reached","Not reached",INDEX(ENGINE!$D$2:$D$102,MATCH($J18,ENGINE!$A$2:$A$102,0))) -> 15500 | G18: =IF($J18="Not reached","Not reached",$E18) -> 101331.08 | H18: =IF($J18="Not reached","Not reached",IFERROR(SUMIFS(ENGINE!$AH$2:$AH$102,ENGINE!$A$2:$A$102,"<="&$J18)/SUMIFS(ENGINE!$Y$2:$Y$102,ENGINE!$A$2:$A$102,"<="&$J18),0)) -> 0.14833373 | J18: {=IFERROR(INDEX(ENGINE!$A$2:$A$102,_xlfn.AGGREGATE(15,6,(ROW(ENGINE!$A$2:$A$102)-ROW(ENGINE!$A$2)+1)/(((ENGINE!$AI$2:$AI$102-ENGINE!$D$2:$D$102)>=$B18)*(ENGINE!$A$2:$A$102<>"")),1)),"Not reached")} -> 13
A19: Disposable Take-Home Pay | B19: 250000 | C19: =IF($J19="Not reached","Not reached",$J19) -> Not reached | D19: =IF($J19="Not reached","Not reached",INDEX(ENGINE!$B$2:$B$102,MATCH($J19,ENGINE!$A$2:$A$102,0))) -> Not reached | E19: =IF($J19="Not reached","Not reached",INDEX(ENGINE!$AI$2:$AI$102,MATCH($J19,ENGINE!$A$2:$A$102,0))-INDEX(ENGINE!$D$2:$D$102,MATCH($J19,ENGINE!$A$2:$A$102,0))) -> Not reached | F19: =IF($J19="Not reached","Not reached",INDEX(ENGINE!$D$2:$D$102,MATCH($J19,ENGINE!$A$2:$A$102,0))) -> Not reached | G19: =IF($J19="Not reached","Not reached",$E19) -> Not reached | H19: =IF($J19="Not reached","Not reached",IFERROR(SUMIFS(ENGINE!$AH$2:$AH$102,ENGINE!$A$2:$A$102,"<="&$J19)/SUMIFS(ENGINE!$Y$2:$Y$102,ENGINE!$A$2:$A$102,"<="&$J19),0)) -> Not reached | J19: {=IFERROR(INDEX(ENGINE!$A$2:$A$102,_xlfn.AGGREGATE(15,6,(ROW(ENGINE!$A$2:$A$102)-ROW(ENGINE!$A$2)+1)/(((ENGINE!$AI$2:$AI$102-ENGINE!$D$2:$D$102)>=$B19)*(ENGINE!$A$2:$A$102<>"")),1)),"Not reached")} -> Not reached

Sheet WHAT-IF SCENARIOS
A1: WHAT-IF SCENARIOS
A2: Isolated shadow calculations for exploring alternate assumptions. None of these inputs affect ENGINE, PERIODIC ENGINE, or any existing chart or output.
A4: 1. REQUIRED RETURN SOLVER
A5: This section is fully isolated from the rest of the model. It does not read or change your main return-rate assumption, and running Goal Seek here will never affect any chart or output elsewhere in the workbook.
A6: Target retirement balance ($) | B6: 2000000 | C6: What you want your balance to reach by retirement
A7: Target in nominal or real (today's) dollars? | B7: Nominal | C7: Real = today's purchasing power; Nominal = actual future dollars
A8: Solver Return Rate (%), isolated: does not affect the rest of the model | B8: 0.1 | C8: Goal Seek changes THIS cell only. It defaults to your main return rate.
A10: Shadow Terminal Balance (at Solver Rate) | B10: =SUM('PERIODIC ENGINE'!$U$2:$U$102)+INPUTS!$C$8*(1+B8)^(Horizon_Rows*'PERIODIC ENGINE'!$S$3) -> 11101633 | C10: Total balance the shadow schedule reaches at the Solver Rate
A11: Nominal Target (converted from Real if needed) | B11: =IF(B7="Real",B6*(1+INPUTS!$C$11)^Horizon_Years,B6) -> 2000000 | C11: What Shadow Terminal Balance must equal, in future dollars
A12: Difference (Shadow − Target) | B12: =B10-B11 -> 9101633.3 | C12: ~$0 after Goal Seek converges; nonzero before it's run
A13: Required Annual Return (Solver Return Rate, once solved) | B13: =B8 -> 0.1 | C13: This is the answer, once Goal Seek has been run
A15: HOW TO SOLVE
A16: Data, then What-If Analysis, then Goal Seek. Set cell: B10. To value: type the number currently shown in B11 (or 0 if using the Difference cell as "Set cell" instead; see below). By changing cell: B8. Click OK.
A17: Tip: for a cleaner solve, you can instead set "Set cell" to B12 (Difference) and "To value" to 0. It's mathematically identical, but lets you watch the gap close to exactly zero.
A20: 2. RETURN-RATE SCENARIOS (BEAR / BASE / BULL)
A21: Bear and Bull are relative to your actual base-case return rate, not fixed values, so they stay meaningful no matter what your real assumption is.
A22: Bear/Bull spread (± percentage points) | B22: 3 | C22: Applied above and below your base return rate
A24: Scenario | B24: Return Rate | C24: Final Nominal Balance | D24: Final Real Balance
A25: Bear (Base − Spread, floored at 0%) | B25: =MAX(0,INPUTS!$C$10-$B$22/100) -> 0.07 | C25: =SUM('PERIODIC ENGINE'!$W$2:$W$102)+INPUTS!$C$8*(1+B25)^(Horizon_Rows*'PERIODIC ENGINE'!$S$3) -> 5498285.3 | D25: =C25/(1+INPUTS!$C$11)^Horizon_Years -> 448822.96
A26: Base (live from main model) | B26: =INPUTS!$C$10 -> 0.1 | C26: =SUM('PERIODIC ENGINE'!$Q$2:$Q$102)+INPUTS!$C$8*(1+B26)^(Horizon_Rows*'PERIODIC ENGINE'!$S$3) -> 11101633 | D26: =C26/(1+INPUTS!$C$11)^Horizon_Years -> 906222.15
A27: Bull (Base + Spread) | B27: =INPUTS!$C$10+$B$22/100 -> 0.13 | C27: =SUM('PERIODIC ENGINE'!$Y$2:$Y$102)+INPUTS!$C$8*(1+B27)^(Horizon_Rows*'PERIODIC ENGINE'!$S$3) -> 24513236 | D27: =C27/(1+INPUTS!$C$11)^Horizon_Years -> 2001006.2
A30: 3. INFLATION SWING
A31: Same relative-offset principle: Low/High inflation move with your actual base inflation assumption, not fixed values. Nominal balance never changes here; only its real-dollar conversion does.
A32: Inflation swing (± percentage points) | B32: 1.5 | C32: Applied above and below your base inflation rate
A34: Inflation Scenario | B34: Rate | C34: Real Balance at Retirement
A35: Low (Base − Swing, floored at 0%) | B35: =MAX(0,INPUTS!$C$11-$B$32/100) -> 0.045 | C35: =$C$26/(1+B35)^Horizon_Years -> 1672578
A36: Base (live from main model) | B36: =INPUTS!$C$11 -> 0.06 | C36: =$C$26/(1+B36)^Horizon_Years -> 906222.15
A37: High (Base + Swing) | B37: =INPUTS!$C$11+$B$32/100 -> 0.075 | C37: =$C$26/(1+B37)^Horizon_Years -> 495248.21
A40: 4. CONTRIBUTION GAP / CAREER BREAK
A41: Gap start year (Projection Year, 0 = first modeled year) | B41: 0
A42: Gap length (years) | B42: 0
A44: Scenario | B44: Final Nominal Balance | C44: Difference vs. Base Case
A45: No gap (base case) | B45: =$C$26 -> 11101633 | C45: N/A
A46: With gap | B46: =SUM('PERIODIC ENGINE'!$AA$2:$AA$102)+INPUTS!$C$8*(1+INPUTS!$C$10)^(Horizon_Rows*'PERIODIC ENGINE'!$S$3) -> 11101633 | C46: =B46-B45 -> 0
A48: 5. EARLY STOP CONTRIBUTING
A49: Stop contributing after age (last contribution happens at this age) | B49: 45 | C49: Contributions stop for good after this age; balance keeps compounding to retirement
A51: Scenario | B51: Final Nominal Balance | C51: Difference vs. Base Case
A52: Contribute full career (base case) | B52: =$C$26 -> 11101633 | C52: N/A
A53: Stop early | B53: =SUM('PERIODIC ENGINE'!$AC$2:$AC$102)+INPUTS!$C$8*(1+INPUTS!$C$10)^(Horizon_Rows*'PERIODIC ENGINE'!$S$3) -> 7860628.3 | C53: =B53-B52 -> -3241005

Sheet CONSTANTS & REFERENCES
A1: CONSTANTS & REFERENCES: 2026 BASE YEAR | F1: Model-linked constants remain in fixed cells; research-only sections are labeled below.
A2: 2026 FEDERAL INCOME TAX BRACKETS & STANDARD DEDUCTIONS
A3: Single / Married Filing Separately | F3: Married Filing Jointly / Qualifying Surviving Spouse | K3: Head of Household
A4: Marginal rate | B4: Taxable income from | C4: Taxable income to | D4: Full-bracket tax | F4: Marginal rate | G4: Taxable income from | H4: Taxable income to | I4: Full-bracket tax | K4: Marginal rate | L4: Taxable income from | M4: Taxable income to | N4: Full-bracket tax
A5: 0.1 | B5: 0 | C5: 12400 | D5: =A5*(C5-B5) -> 1240 | F5: 0.1 | G5: 0 | H5: 24800 | I5: =F5*(H5) -> 2480 | K5: 0.1 | L5: 0 | M5: 17700 | N5: =K5*(M5) -> 1770
A6: 0.12 | B6: =C5+1 -> 12401 | C6: 50400 | D6: =A6*(C6-B6+1) -> 4560 | F6: 0.12 | G6: =H5+1 -> 24801 | H6: 100800 | I6: =F6*(H6-G6) -> 9119.88 | K6: 0.12 | L6: =M5+1 -> 17701 | M6: 67450 | N6: =K6*(M6-L6) -> 5969.88
A7: 0.22 | B7: =C6+1 -> 50401 | C7: 105700 | D7: =A7*(C7-B7+1) -> 12166 | F7: 0.22 | G7: =H6+1 -> 100801 | H7: 211400 | I7: =F7*(H7-G7) -> 24331.78 | K7: 0.22 | L7: =M6+1 -> 67451 | M7: 105700 | N7: =K7*(M7-L7) -> 8414.78
A8: 0.24 | B8: =C7+1 -> 105701 | C8: 201775 | D8: =A8*(C8-B8+1) -> 23058 | F8: 0.24 | G8: =H7+1 -> 211401 | H8: 403550 | I8: =F8*(H8-G8) -> 46115.76 | K8: 0.24 | L8: =M7+1 -> 105701 | M8: 201700 | N8: =K8*(M8-L8) -> 23039.76
A9: 0.32 | B9: =C8+1 -> 201776 | C9: 256225 | D9: =A9*(C9-B9+1) -> 17424 | F9: 0.32 | G9: =H8+1 -> 403551 | H9: 512450 | I9: =F9*(H9-G9) -> 34847.68 | K9: 0.32 | L9: =M8+1 -> 201701 | M9: 256200 | N9: =K9*(M9-L9) -> 17439.68
A10: 0.35 | B10: =C9+1 -> 256226 | C10: 646600 | D10: =A10*(C10-B10+1) -> 136631.25 | F10: 0.35 | G10: =H9+1 -> 512451 | H10: 768600 | I10: =F10*(H10-G10) -> 89652.15 | K10: 0.35 | L10: =M9+1 -> 256201 | M10: 640600 | N10: =K10*(M10-L10) -> 134539.65
A11: 0.37 | B11: =C10 -> 646600 | F11: 0.37 | G11: =H10 -> 768600 | K11: 0.37 | L11: =M10 -> 640600
A12: 2026 standard deduction | F12: 2026 standard deduction | K12: 2026 standard deduction
A13: Single / Separately | B13: 16100 | C13: Single_Separately_STD_Deduction | F13: Jointly / Spouse | G13: 32200 | K13: Head of Household | L13: 24150
A15: Supporting indexing and rounding constants | B15: Value | C15: Notes
A16: Bracket rounding increment (Single / Joint / HoH) | B16: 50 | C16: Bracket_Round_Standard: statutory rounding for Single, Married Filing Jointly, and Head of Household (IRC §1(f)(6)/(7))
A17: Bracket rounding increment (Married Filing Separately) | B17: 25 | C17: Bracket_Round_MFS: MFS brackets round to the nearest $25, not $50, per IRC §1(f)(7)/(8)
A18: Standard deduction rounding increment | B18: 50 | C18: Supporting reference for deduction rounding
A20: 2026 PAYROLL TAX RATES & THRESHOLDS
A21: Tax component | B21: Employee rate | C21: Wage base / threshold | D21: Model note
A22: OASDI | B22: 0.062 | C22: 184500 | D22: Gross Income (capped)
A23: Note: This model escalates the OASDI wage base using CPI as a simplified illustrative proxy (see 'Modeled OASDI Wage Base' column on ENGINE); row 21 is the 2026 base year value only. This is NOT how the SSA actually indexes the wage base: the real annual adjustment is tied to the National Average Wage Index (AWI), not CPI. Treat the modeled figures as a rough approximation, not an official forecast.
A24: Medicare | B24: 0.0145 | C24: No Limit | D24: All Gross Income
A25: Additional Medicare Tax (Single) | B25: 0.009 | C25: 200000 | D25: GI over threshold (Single)
A26: Additional Medicare Tax (Joint) | B26: 0.009 | C26: 250000 | D26: GI over threshold (Jointly)
A27: Additional Medicare Tax (Married Filing Separately) | B27: 0.009 | C27: 125000 | D27: GI over threshold (Married Filing Separately)
A28: Additional Medicare Tax (Head of Household) | B28: 0.009 | C28: 200000 | D28: GI over threshold (Head of Household)
A29: 2026 IRA LIMITS & ROUNDING CONSTANTS
A30: Reference item | B30: 2026 value | C30: Purpose
A31: Regular IRA contribution limit | B31: 7500 | C31: 2026 published regular IRA limit, per IRS Notice 2025-67
A32: Age-50+ catch-up limit | B32: 1100 | C32: 2026 age-50+ catch-up amount
A33: Regular limit rounding increment | B33: 500 | C33: Regular IRA limit statutory rounding increment
A34: Catch-up rounding increment | B34: 100 | C34: Catch-up statutory rounding increment
A35: RESEARCH NOTES: NOT CONNECTED TO CURRENT ENGINE
A36: 2026 FEDERAL TAX HEADLINE REFERENCES
A37: Single 10% bracket upper bound | B37: 12400 | C37: 10% applies to taxable income from $0 through $12,400.
A38: Single standard deduction | B38: 16100 | C38: Taxable income generally starts after deductions.
A39: Approx. gross income before 12% begins | B39: =B37+B38 -> 28500 | C39: Illustrative gross threshold = bracket ceiling + standard deduction.
A41: 2026 IRA MAGI RESEARCH: NOT MODELED | D41: Roth reduction mechanics
A42: Filing status | B42: Lower bound | C42: Upper bound | D42: Phase-out percentage | E42: Phase-out fraction: (MAGI - Lower) / (Upper - Lower)
A43: Single / Head of Household | B43: 153000 | C43: 168000 | D43: Preliminary limit | E43: Max contribution × (1 - phase-out percentage)
...

Sheet ENGINE
